Workbook

Sheet Key Insights
B1: KEY INSIGHTS – Attendance vs Performance Analysis
B3: INSIGHT 1 | C3: Positive Correlation Confirmed
C4: ="Students with HIGH attendance averaged "&TEXT(AVERAGEIF('Raw Data'!$F$3:$F$51,"High (90-100%)",'Raw Data'!$E$3:$E$51),"0.0")&"% overall vs "&TEXT(AVERAGEIF('Raw Data'!$F$3:$F$51,"Low (<75%)",'Raw Data'!$E$3:$E$51),"0.0")&"% for LOW attendance." -> Students with HIGH attendance averaged 65.5% overall vs 58.3% for LOW attendance.
B5: INSIGHT 2 | C5: Grade A Students
C6: =COUNTIF('Raw Data'!$G$3:$G$51,"A")&" students achieved Grade A (>80%). All are in Medium or High attendance groups." -> 4 students achieved Grade A (>80%). All are in Medium or High attendance groups.
B7: INSIGHT 3 | C7: At-Risk Count
C8: =COUNTIF('Raw Data'!$H$3:$H$51,"YES")&" students flagged YES risk + "&COUNTIF('Raw Data'!$H$3:$H$51,"Academic Risk")&" Academic Risk. Total "&(COUNTIF('Raw Data'!$H$3:$H$51,"YES")+COUNTIF('Raw Data'!$H$3:$H$51,"Academic Risk"))&" students need support." -> 8 students flagged YES risk + 14 Academic Risk. Total 22 students need support.
B9: INSIGHT 4 | C9: Grade F Warning
C10: =COUNTIF('Raw Data'!$G$3:$G$51,"F")&" students scored Grade F (<50% overall). Immediate academic intervention required." -> 8 students scored Grade F (<50% overall). Immediate academic intervention required.
B11: AHA MOMENT | C11: Outliers Tell a Deeper Story
C12: Some students with high attendance still scored Grade D or F — proving attendance alone is not enough. Active engagement and study habits matter equally. Students flagged 'High Att / Low Perf' need pedagogical review.
B13: REGRESSION | C13: CT predicts Term (r=0.749, R²=0.56)
C14: Equation: Term % = 23.33 + 0.633 × CT%. For every 1% rise in CT score, Term rises 0.633%. CT explains 56% of Term variance. 44% depends on other factors.
B15: TRANSITION | C15: Grade Stability (CT→Term)
C16: The Transition Matrix shows how many students maintained, improved, or dropped their grade band from Class Test to Term Exam. A high diagonal probability means CT grades reliably predict Term grades.
B17: Prediction of Final Term Grades | C17: Used transition matrix of midterms to get pridictions of grades in Fina Term
C18: A transition matrix was used to predict final term results based on class test performance. Class test grades were converted into percentages and multiplied with the transition matrix using MMULT to estimate the final grade distribution.
C19: The output gave the expected percentage of students in each grade for the final term. These percentages were then converted into approximate counts based on a total class size of 51 students.
C20: Overall, the model shows how students are expected to move between grade categories and helps predict final exam performance using past assessment trends.

Sheet Raw Data
A1: The Aster School – Mid Term 2025-26 | Student Performance Dataset
A2: Student Name | B2: Grade | C2: Attendance % | D2: Math % | E2: Overall % | F2: Attendance Group | G2: Grade2 | H2: At-Risk | I2: Outlier Flag
A3: Abdullah Ayaz | B3: 7 | C3: 90 | D3: 80 | E3: 76.2 | F3: =IF(C3>=90,"High (90-100%)",IF(C3>=75,"Medium (75-89%)","Low (<75%)")) -> High (90-100%) | G3: =IF(E3="","F",IF(E3>80,"A",IF(E3>=70,"B",IF(E3>=60,"C",IF(E3>=50,"D","F"))))) -> B | H3: =IF(AND(C3<75,E3<60),"YES",IF(AND(C3>=75,E3<60),"Academic Risk","NO")) -> NO | I3: =IF(AND(C3>=85,E3<55),"High Att / Low Perf",IF(AND(C3<75,E3>=65),"Low Att / High Perf","Normal")) -> Normal
A4: Omer Razi | B4: 7 | C4: 88 | D4: 84 | E4: 75.2 | F4: =IF(C4>=90,"High (90-100%)",IF(C4>=75,"Medium (75-89%)","Low (<75%)")) -> Medium (75-89%) | G4: =IF(E4="","F",IF(E4>80,"A",IF(E4>=70,"B",IF(E4>=60,"C",IF(E4>=50,"D","F"))))) -> B | H4: =IF(AND(C4<75,E4<60),"YES",IF(AND(C4>=75,E4<60),"Academic Risk","NO")) -> NO | I4: =IF(AND(C4>=85,E4<55),"High Att / Low Perf",IF(AND(C4<75,E4>=65),"Low Att / High Perf","Normal")) -> Normal
A5: Muqaddas Jamal | B5: 7 | C5: 78 | D5: 35 | E5: 50.6 | F5: =IF(C5>=90,"High (90-100%)",IF(C5>=75,"Medium (75-89%)","Low (<75%)")) -> Medium (75-89%) | G5: =IF(E5="","F",IF(E5>80,"A",IF(E5>=70,"B",IF(E5>=60,"C",IF(E5>=50,"D","F"))))) -> D | H5: =IF(AND(C5<75,E5<60),"YES",IF(AND(C5>=75,E5<60),"Academic Risk","NO")) -> Academic Risk | I5: =IF(AND(C5>=85,E5<55),"High Att / Low Perf",IF(AND(C5<75,E5>=65),"Low Att / High Perf","Normal")) -> Normal
A6: Hamnah Shafi | B6: 7 | C6: 89 | D6: 56 | E6: 54.9 | F6: =IF(C6>=90,"High (90-100%)",IF(C6>=75,"Medium (75-89%)","Low (<75%)")) -> Medium (75-89%) | G6: =IF(E6="","F",IF(E6>80,"A",IF(E6>=70,"B",IF(E6>=60,"C",IF(E6>=50,"D","F"))))) -> D | H6: =IF(AND(C6<75,E6<60),"YES",IF(AND(C6>=75,E6<60),"Academic Risk","NO")) -> Academic Risk | I6: =IF(AND(C6>=85,E6<55),"High Att / Low Perf",IF(AND(C6<75,E6>=65),"Low Att / High Perf","Normal")) -> High Att / Low Perf
A7: Zeenia Zohaib | B7: 7 | C7: 72 | D7: 55 | E7: 45.8 | F7: =IF(C7>=90,"High (90-100%)",IF(C7>=75,"Medium (75-89%)","Low (<75%)")) -> Low (<75%) | G7: =IF(E7="","F",IF(E7>80,"A",IF(E7>=70,"B",IF(E7>=60,"C",IF(E7>=50,"D","F"))))) -> F | H7: =IF(AND(C7<75,E7<60),"YES",IF(AND(C7>=75,E7<60),"Academic Risk","NO")) -> YES | I7: =IF(AND(C7>=85,E7<55),"High Att / Low Perf",IF(AND(C7<75,E7>=65),"Low Att / High Perf","Normal")) -> Normal
A8: Umer Adil | B8: 7 | C8: 70 | D8: 61 | E8: 66 | F8: =IF(C8>=90,"High (90-100%)",IF(C8>=75,"Medium (75-89%)","Low (<75%)")) -> Low (<75%) | G8: =IF(E8="","F",IF(E8>80,"A",IF(E8>=70,"B",IF(E8>=60,"C",IF(E8>=50,"D","F"))))) -> C | H8: =IF(AND(C8<75,E8<60),"YES",IF(AND(C8>=75,E8<60),"Academic Risk","NO")) -> NO | I8: =IF(AND(C8>=85,E8<55),"High Att / Low Perf",IF(AND(C8<75,E8>=65),"Low Att / High Perf","Normal")) -> Low Att / High Perf
A9: Inayah Sabahat | B9: 7 | C9: 78 | D9: 89 | E9: 77.6 | F9: =IF(C9>=90,"High (90-100%)",IF(C9>=75,"Medium (75-89%)","Low (<75%)")) -> Medium (75-89%) | G9: =IF(E9="","F",IF(E9>80,"A",IF(E9>=70,"B",IF(E9>=60,"C",IF(E9>=50,"D","F"))))) -> B | H9: =IF(AND(C9<75,E9<60),"YES",IF(AND(C9>=75,E9<60),"Academic Risk","NO")) -> NO | I9: =IF(AND(C9>=85,E9<55),"High Att / Low Perf",IF(AND(C9<75,E9>=65),"Low Att / High Perf","Normal")) -> Normal
A10: Ayaan Amin | B10: 7 | C10: 83 | D10: 67 | E10: 48.5 | F10: =IF(C10>=90,"High (90-100%)",IF(C10>=75,"Medium (75-89%)","Low (<75%)")) -> Medium (75-89%) | G10: =IF(E10="","F",IF(E10>80,"A",IF(E10>=70,"B",IF(E10>=60,"C",IF(E10>=50,"D","F"))))) -> F | H10: =IF(AND(C10<75,E10<60),"YES",IF(AND(C10>=75,E10<60),"Academic Risk","NO")) -> Academic Risk | I10: =IF(AND(C10>=85,E10<55),"High Att / Low Perf",IF(AND(C10<75,E10>=65),"Low Att / High Perf","Normal")) -> Normal
A11: Muhammad Umer | B11: 7 | C11: 87 | D11: 83 | E11: 69 | F11: =IF(C11>=90,"High (90-100%)",IF(C11>=75,"Medium (75-89%)","Low (<75%)")) -> Medium (75-89%) | G11: =IF(E11="","F",IF(E11>80,"A",IF(E11>=70,"B",IF(E11>=60,"C",IF(E11>=50,"D","F"))))) -> C | H11: =IF(AND(C11<75,E11<60),"YES",IF(AND(C11>=75,E11<60),"Academic Risk","NO")) -> NO | I11: =IF(AND(C11>=85,E11<55),"High Att / Low Perf",IF(AND(C11<75,E11>=65),"Low Att / High Perf","Normal")) -> Normal
A12: Hamza Naveed | B12: 7 | C12: 63 | D12: 82 | E12: 68.8 | F12: =IF(C12>=90,"High (90-100%)",IF(C12>=75,"Medium (75-89%)","Low (<75%)")) -> Low (<75%) | G12: =IF(E12="","F",IF(E12>80,"A",IF(E12>=70,"B",IF(E12>=60,"C",IF(E12>=50,"D","F"))))) -> C | H12: =IF(AND(C12<75,E12<60),"YES",IF(AND(C12>=75,E12<60),"Academic Risk","NO")) -> NO | I12: =IF(AND(C12>=85,E12<55),"High Att / Low Perf",IF(AND(C12<75,E12>=65),"Low Att / High Perf","Normal")) -> Low Att / High Perf
A13: Omar Borra | B13: 7 | C13: 80 | D13: 56 | E13: 64.2 | F13: =IF(C13>=90,"High (90-100%)",IF(C13>=75,"Medium (75-89%)","Low (<75%)")) -> Medium (75-89%) | G13: =IF(E13="","F",IF(E13>80,"A",IF(E13>=70,"B",IF(E13>=60,"C",IF(E13>=50,"D","F"))))) -> C | H13: =IF(AND(C13<75,E13<60),"YES",IF(AND(C13>=75,E13<60),"Academic Risk","NO")) -> NO | I13: =IF(AND(C13>=85,E13<55),"High Att / Low Perf",IF(AND(C13<75,E13>=65),"Low Att / High Perf","Normal")) -> Normal
A14: Umer Imran | B14: 7 | C14: 68 | D14: 35 | E14: 39.8 | F14: =IF(C14>=90,"High (90-100%)",IF(C14>=75,"Medium (75-89%)","Low (<75%)")) -> Low (<75%) | G14: =IF(E14="","F",IF(E14>80,"A",IF(E14>=70,"B",IF(E14>=60,"C",IF(E14>=50,"D","F"))))) -> F | H14: =IF(AND(C14<75,E14<60),"YES",IF(AND(C14>=75,E14<60),"Academic Risk","NO")) -> YES | I14: =IF(AND(C14>=85,E14<55),"High Att / Low Perf",IF(AND(C14<75,E14>=65),"Low Att / High Perf","Normal")) -> Normal
... A51: Muhammad Sohan Ashiq | B51: 6 | C51: 75 | D51: 21 | E51: 34.7 | F51: =IF(C51>=90,"High (90-100%)",IF(C51>=75,"Medium (75-89%)","Low (<75%)")) -> Medium (75-89%) | G51: =IF(E51="","F",IF(E51>80,"A",IF(E51>=70,"B",IF(E51>=60,"C",IF(E51>=50,"D","F"))))) -> F | H51: =IF(AND(C51<75,E51<60),"YES",IF(AND(C51>=75,E51<60),"Academic Risk","NO")) -> Academic Risk | I51: =IF(AND(C51>=85,E51<55),"High Att / Low Perf",IF(AND(C51<75,E51>=65),"Low Att / High Perf","Normal")) -> Normal

Sheet Group Analysis
A1: Attendance Group Analysis – Performance Comparison
A3: SECTION A – GROUP SUMMARY TABLE
A4: Attendance Group | B4: # Students | C4: Avg Attendance % | D4: Avg Math % | E4: Avg Overall % | F4: Highest Overall | G4: Lowest Overall
A5: High (90-100%) | B5: =COUNTIF('Raw Data'!$F$3:$F$51,"High (90-100%)") -> 5 | C5: =AVERAGEIF('Raw Data'!$F$3:$F$51,"High (90-100%)",'Raw Data'!$C$3:$C$51) -> 95 | D5: =AVERAGEIF('Raw Data'!$F$3:$F$51,"High (90-100%)",'Raw Data'!$D$3:$D$51) -> 65.6 | E5: =AVERAGEIF('Raw Data'!$F$3:$F$51,"High (90-100%)",'Raw Data'!$E$3:$E$51) -> 65.48 | F5: =MAX(IF('Raw Data'!$F$3:$F$51="High (90-100%)",'Raw Data'!$E$3:$E$51)) -> 0 | G5: =MIN(IF('Raw Data'!$F$3:$F$51="High (90-100%)",'Raw Data'!$E$3:$E$51)) -> 0
A6: Medium (75-89%) | B6: =COUNTIF('Raw Data'!$F$3:$F$51,"Medium (75-89%)") -> 27 | C6: =AVERAGEIF('Raw Data'!$F$3:$F$51,"Medium (75-89%)",'Raw Data'!$C$3:$C$51) -> 83.407407 | D6: =AVERAGEIF('Raw Data'!$F$3:$F$51,"Medium (75-89%)",'Raw Data'!$D$3:$D$51) -> 63.481481 | E6: =AVERAGEIF('Raw Data'!$F$3:$F$51,"Medium (75-89%)",'Raw Data'!$E$3:$E$51) -> 63.175185 | F6: =MAX(IF('Raw Data'!$F$3:$F$51="Medium (75-89%)",'Raw Data'!$E$3:$E$51)) -> 83.1 | G6: =MIN(IF('Raw Data'!$F$3:$F$51="Medium (75-89%)",'Raw Data'!$E$3:$E$51)) -> 34.7
A7: Low (<75%) | B7: =COUNTIF('Raw Data'!$F$3:$F$51,"Low (<75%)") -> 17 | C7: =AVERAGEIF('Raw Data'!$F$3:$F$51,"Low (<75%)",'Raw Data'!$C$3:$C$51) -> 67.882353 | D7: =AVERAGEIF('Raw Data'!$F$3:$F$51,"Low (<75%)",'Raw Data'!$D$3:$D$51) -> 53.470588 | E7: =AVERAGEIF('Raw Data'!$F$3:$F$51,"Low (<75%)",'Raw Data'!$E$3:$E$51) -> 58.275882 | F7: =MAX(IF('Raw Data'!$F$3:$F$51="Low (<75%)",'Raw Data'!$E$3:$E$51)) -> 83.1 | G7: =MIN(IF('Raw Data'!$F$3:$F$51="Low (<75%)",'Raw Data'!$E$3:$E$51)) -> 34.7
A8: SECTION B – AT-RISK STUDENTS
A9: Definition: Attendance < 75% AND Overall % < 60%
A10: Student Name | B10: Grade | C10: Attendance % | D10: Overall % | E10: Math % | F10: Grade
A11: Zeenia Zohaib | B11: 7 | C11: 72 | D11: 45.8 | E11: 55 | F11: =IF(D11="","F",IF(D11>80,"A",IF(D11>=70,"B",IF(D11>=60,"C",IF(D11>=50,"D","F"))))) -> F
A12: Umer Imran | B12: 7 | C12: 68 | D12: 39.8 | E12: 35 | F12: =IF(D12="","F",IF(D12>80,"A",IF(D12>=70,"B",IF(D12>=60,"C",IF(D12>=50,"D","F"))))) -> F
A13: Abdul Razzaq | B13: 7 | C13: 66 | D13: 50.6 | E13: 60 | F13: =IF(D13="","F",IF(D13>80,"A",IF(D13>=70,"B",IF(D13>=60,"C",IF(D13>=50,"D","F"))))) -> D
A14: Syed Muzzammil Hassan | B14: 8 | C14: 73 | D14: 57.18 | E14: 70 | F14: =IF(D14="","F",IF(D14>80,"A",IF(D14>=70,"B",IF(D14>=60,"C",IF(D14>=50,"D","F"))))) -> D
A15: Alishba Haider | B15: 8 | C15: 63 | D15: 40.64 | E15: 17 | F15: =IF(D15="","F",IF(D15>80,"A",IF(D15>=70,"B",IF(D15>=60,"C",IF(D15>=50,"D","F"))))) -> F
A16: Ali Hasan | B16: 8 | C16: 60 | D16: 43 | E16: 44 | F16: =IF(D16="","F",IF(D16>80,"A",IF(D16>=70,"B",IF(D16>=60,"C",IF(D16>=50,"D","F"))))) -> F
A17: Muhammad Ahmed | B17: 8 | C17: 66 | D17: 41.18 | E17: 6 | F17: =IF(D17="","F",IF(D17>80,"A",IF(D17>=70,"B",IF(D17>=60,"C",IF(D17>=50,"D","F"))))) -> F
A18: Aysel Hammad | B18: 6 | C18: 62 | D18: 59.1 | E18: 38 | F18: =IF(D18="","F",IF(D18>80,"A",IF(D18>=70,"B",IF(D18>=60,"C",IF(D18>=50,"D","F"))))) -> D
A19: TOTAL AT-RISK | B19: =COUNTIF('Raw Data'!$H$3:$H$51,"YES") -> 8 | C19: TOTAL ACADEMIC RISK | D19: =COUNTIF('Raw Data'!$H$3:$H$51,"Academic Risk") -> 14
A21: SECTION C – OUTLIER STUDENTS
A22: Student Name | B22: Grade | C22: Attendance % | D22: Overall % | E22: Grade | F22: Outlier Type
A23: Hamnah Shafi | B23: 7 | C23: 89 | D23: 54.9 | E23: =IF(D23="","F",IF(D23>80,"A",IF(D23>=70,"B",IF(D23>=60,"C",IF(D23>=50,"D","F"))))) -> D | F23: High Att / Low Perf
A24: Umer Adil | B24: 7 | C24: 70 | D24: 66 | E24: =IF(D24="","F",IF(D24>80,"A",IF(D24>=70,"B",IF(D24>=60,"C",IF(D24>=50,"D","F"))))) -> C | F24: Low Att / High Perf
A25: Hamza Naveed | B25: 7 | C25: 63 | D25: 68.8 | E25: =IF(D25="","F",IF(D25>80,"A",IF(D25>=70,"B",IF(D25>=60,"C",IF(D25>=50,"D","F"))))) -> C | F25: Low Att / High Perf
A26: Mahad Sajid | B26: 8 | C26: 63 | D26: 67.18 | E26: =IF(D26="","F",IF(D26>80,"A",IF(D26>=70,"B",IF(D26>=60,"C",IF(D26>=50,"D","F"))))) -> C | F26: Low Att / High Perf
A27: Fatima Abdul Qadir | B27: 8 | C27: 72 | D27: 74.64 | E27: =IF(D27="","F",IF(D27>80,"A",IF(D27>=70,"B",IF(D27>=60,"C",IF(D27>=50,"D","F"))))) -> B | F27: Low Att / High Perf
A28: Mirha Farhan | B28: 8 | C28: 88 | D28: 50.09 | E28: =IF(D28="","F",IF(D28>80,"A",IF(D28>=70,"B",IF(D28>=60,"C",IF(D28>=50,"D","F"))))) -> D | F28: High Att / Low Perf
A29: Abeeha Ali Khan | B29: 8 | C29: 72 | D29: 80.64 | E29: =IF(D29="","F",IF(D29>80,"A",IF(D29>=70,"B",IF(D29>=60,"C",IF(D29>=50,"D","F"))))) -> A | F29: Low Att / High Perf
A30: Anaya Rameez | B30: 6 | C30: 74 | D30: 66.2 | E30: =IF(D30="","F",IF(D30>80,"A",IF(D30>=70,"B",IF(D30>=60,"C",IF(D30>=50,"D","F"))))) -> C | F30: Low Att / High Perf
A31: Raayan Ibrahim | B31: 6 | C31: 67 | D31: 69.3 | E31: =IF(D31="","F",IF(D31>80,"A",IF(D31>=70,"B",IF(D31>=60,"C",IF(D31>=50,"D","F"))))) -> C | F31: Low Att / High Perf
A32: Muhammad Hussain Raza | B32: 6 | C32: 100 | D32: 50.7 | E32: =IF(D32="","F",IF(D32>80,"A",IF(D32>=70,"B",IF(D32>=60,"C",IF(D32>=50,"D","F"))))) -> D | F32: High Att / Low Perf
A33: Alisha Arif | B33: 6 | C33: 93 | D33: 51.4 | E33: =IF(D33="","F",IF(D33>80,"A",IF(D33>=70,"B",IF(D33>=60,"C",IF(D33>=50,"D","F"))))) -> D | F33: High Att / Low Perf

Sheet Top & Bottom
A1: Top 10 & Bottom 10 Students by Overall Performance
A3: 🏆 TOP 10 PERFORMERS
A4: Rank | B4: Student Name | C4: Grade | D4: Attendance % | E4: Math % | F4: Overall % | G4: Grade
A5: 1 | B5: Eeshal Amin | C5: 6 | D5: 83 | E5: 85 | F5: 83.1 | G5: =IF(F5="","F",IF(F5>80,"A",IF(F5>=70,"B",IF(F5>=60,"C",IF(F5>=50,"D","F"))))) -> A
A6: 2 | B6: Umaiza Omer | C6: 6 | D6: 86 | E6: 69 | F6: 81.3 | G6: =IF(F6="","F",IF(F6>80,"A",IF(F6>=70,"B",IF(F6>=60,"C",IF(F6>=50,"D","F"))))) -> A
A7: 3 | B7: Abeeha Ali Khan | C7: 8 | D7: 72 | E7: 74 | F7: 80.64 | G7: =IF(F7="","F",IF(F7>80,"A",IF(F7>=70,"B",IF(F7>=60,"C",IF(F7>=50,"D","F"))))) -> A
A8: 4 | B8: Muhammad Ahmed Ahsan | C8: 6 | D8: 89 | E8: 86 | F8: 80.5 | G8: =IF(F8="","F",IF(F8>80,"A",IF(F8>=70,"B",IF(F8>=60,"C",IF(F8>=50,"D","F"))))) -> A
A9: 5 | B9: Muhammad Sarhan Safder | C9: 6 | D9: 96 | E9: 88 | F9: 79.5 | G9: =IF(F9="","F",IF(F9>80,"A",IF(F9>=70,"B",IF(F9>=60,"C",IF(F9>=50,"D","F"))))) -> B
A10: 6 | B10: Inayah Sabahat | C10: 7 | D10: 78 | E10: 89 | F10: 77.6 | G10: =IF(F10="","F",IF(F10>80,"A",IF(F10>=70,"B",IF(F10>=60,"C",IF(F10>=50,"D","F"))))) -> B
A11: 7 | B11: Muhammad Yahya | C11: 8 | D11: 89 | E11: 76 | F11: 76.64 | G11: =IF(F11="","F",IF(F11>80,"A",IF(F11>=70,"B",IF(F11>=60,"C",IF(F11>=50,"D","F"))))) -> B
A12: 8 | B12: Abdullah Ayaz | C12: 7 | D12: 90 | E12: 80 | F12: 76.2 | G12: =IF(F12="","F",IF(F12>80,"A",IF(F12>=70,"B",IF(F12>=60,"C",IF(F12>=50,"D","F"))))) -> B
A13: 9 | B13: Jannah Saqib | C13: 6 | D13: 75 | E13: 62 | F13: 75.9 | G13: =IF(F13="","F",IF(F13>80,"A",IF(F13>=70,"B",IF(F13>=60,"C",IF(F13>=50,"D","F"))))) -> B
A14: 10 | B14: Omer Razi | C14: 7 | D14: 88 | E14: 84 | F14: 75.2 | G14: =IF(F14="","F",IF(F14>80,"A",IF(F14>=70,"B",IF(F14>=60,"C",IF(F14>=50,"D","F"))))) -> B
A16: ⚠ BOTTOM 10 STUDENTS
A17: Rank | B17: Student Name | C17: Grade | D17: Attendance % | E17: Math % | F17: Overall % | G17: Grade
A18: 1 | B18: Muhammad Sohan Ashiq | C18: 6 | D18: 75 | E18: 21 | F18: 34.7 | G18: =IF(F18="","F",IF(F18>80,"A",IF(F18>=70,"B",IF(F18>=60,"C",IF(F18>=50,"D","F"))))) -> F
A19: 2 | B19: Umer Imran | C19: 7 | D19: 68 | E19: 35 | F19: 39.8 | G19: =IF(F19="","F",IF(F19>80,"A",IF(F19>=70,"B",IF(F19>=60,"C",IF(F19>=50,"D","F"))))) -> F
A20: 3 | B20: Alishba Haider | C20: 8 | D20: 63 | E20: 17 | F20: 40.64 | G20: =IF(F20="","F",IF(F20>80,"A",IF(F20>=70,"B",IF(F20>=60,"C",IF(F20>=50,"D","F"))))) -> F
A21: 4 | B21: Muhammad Hussain Yawar | C21: 8 | D21: 80 | E21: 60 | F21: 40.91 | G21: =IF(F21="","F",IF(F21>80,"A",IF(F21>=70,"B",IF(F21>=60,"C",IF(F21>=50,"D","F"))))) -> F
A22: 5 | B22: Muhammad Ahmed | C22: 8 | D22: 66 | E22: 6 | F22: 41.18 | G22: =IF(F22="","F",IF(F22>80,"A",IF(F22>=70,"B",IF(F22>=60,"C",IF(F22>=50,"D","F"))))) -> F
A23: 6 | B23: Ali Hasan | C23: 8 | D23: 60 | E23: 44 | F23: 43 | G23: =IF(F23="","F",IF(F23>80,"A",IF(F23>=70,"B",IF(F23>=60,"C",IF(F23>=50,"D","F"))))) -> F
A24: 7 | B24: Zeenia Zohaib | C24: 7 | D24: 72 | E24: 55 | F24: 45.8 | G24: =IF(F24="","F",IF(F24>80,"A",IF(F24>=70,"B",IF(F24>=60,"C",IF(F24>=50,"D","F"))))) -> F
A25: 8 | B25: Ayaan Amin | C25: 7 | D25: 83 | E25: 67 | F25: 48.5 | G25: =IF(F25="","F",IF(F25>80,"A",IF(F25>=70,"B",IF(F25>=60,"C",IF(F25>=50,"D","F"))))) -> F
A26: 9 | B26: Mirha Farhan | C26: 8 | D26: 88 | E26: 45 | F26: 50.09 | G26: =IF(F26="","F",IF(F26>80,"A",IF(F26>=70,"B",IF(F26>=60,"C",IF(F26>=50,"D","F"))))) -> D
A27: 10 | B27: Muqaddas Jamal | C27: 7 | D27: 78 | E27: 35 | F27: 50.6 | G27: =IF(F27="","F",IF(F27>80,"A",IF(F27>=70,"B",IF(F27>=60,"C",IF(F27>=50,"D","F"))))) -> D
A28: QUICK STATS (formula-driven)
A29: Class Average Overall % | E29: =AVERAGE('Raw Data'!$E$3:$E$51) -> 61.710612
A30: Highest Overall % | E30: =MAX('Raw Data'!$E$3:$E$51) -> 83.1
A31: Lowest Overall % | E31: =MIN('Raw Data'!$E$3:$E$51) -> 34.7
A32: # Students Grade A | E32: =COUNTIF('Raw Data'!$G$3:$G$51,"A") -> 4
A33: # Students Grade F | E33: =COUNTIF('Raw Data'!$G$3:$G$51,"F") -> 8

Sheet Chart Data
A1: Chart Source Data – Group Average Performance | G1: Scatter Source (Attendance vs Overall %)
A2: Attendance Group | B2: # Students | C2: Avg Attendance % | D2: Avg Math % | E2: Avg Overall % | G2: Student Name | H2: Attendance % | I2: Overall % | J2: Grade
A3: High (90-100%) | B3: =COUNTIF('Raw Data'!$F$3:$F$51,"High (90-100%)") -> 5 | C3: =IFERROR(AVERAGEIF('Raw Data'!$F$3:$F$51,"High (90-100%)",'Raw Data'!$C$3:$C$51),0) -> 95 | D3: =IFERROR(AVERAGEIF('Raw Data'!$F$3:$F$51,"High (90-100%)",'Raw Data'!$D$3:$D$51),0) -> 65.6 | E3: =IFERROR(AVERAGEIF('Raw Data'!$F$3:$F$51,"High (90-100%)",'Raw Data'!$E$3:$E$51),0) -> 65.48 | G3: Abdullah Ayaz | H3: 90 | I3: 76.2 | J3: 7
A4: Medium (75-89%) | B4: =COUNTIF('Raw Data'!$F$3:$F$51,"Medium (75-89%)") -> 27 | C4: =IFERROR(AVERAGEIF('Raw Data'!$F$3:$F$51,"Medium (75-89%)",'Raw Data'!$C$3:$C$51),0) -> 83.407407 | D4: =IFERROR(AVERAGEIF('Raw Data'!$F$3:$F$51,"Medium (75-89%)",'Raw Data'!$D$3:$D$51),0) -> 63.481481 | E4: =IFERROR(AVERAGEIF('Raw Data'!$F$3:$F$51,"Medium (75-89%)",'Raw Data'!$E$3:$E$51),0) -> 63.175185 | G4: Omer Razi | H4: 88 | I4: 75.2 | J4: 7
A5: Low (<75%) | B5: =COUNTIF('Raw Data'!$F$3:$F$51,"Low (<75%)") -> 17 | C5: =IFERROR(AVERAGEIF('Raw Data'!$F$3:$F$51,"Low (<75%)",'Raw Data'!$C$3:$C$51),0) -> 67.882353 | D5: =IFERROR(AVERAGEIF('Raw Data'!$F$3:$F$51,"Low (<75%)",'Raw Data'!$D$3:$D$51),0) -> 53.470588 | E5: =IFERROR(AVERAGEIF('Raw Data'!$F$3:$F$51,"Low (<75%)",'Raw Data'!$E$3:$E$51),0) -> 58.275882 | G5: Muqaddas Jamal | H5: 78 | I5: 50.6 | J5: 7
G6: Hamnah Shafi | H6: 89 | I6: 54.9 | J6: 7
G7: Zeenia Zohaib | H7: 72 | I7: 45.8 | J7: 7
G8: Umer Adil | H8: 70 | I8: 66 | J8: 7
G9: Inayah Sabahat | H9: 78 | I9: 77.6 | J9: 7
G10: Ayaan Amin | H10: 83 | I10: 48.5 | J10: 7
G11: Muhammad Umer | H11: 87 | I11: 69 | J11: 7
G12: Hamza Naveed | H12: 63 | I12: 68.8 | J12: 7
G13: Omar Borra | H13: 80 | I13: 64.2 | J13: 7
G14: Umer Imran | H14: 68 | I14: 39.8 | J14: 7
G15: Ayaan Ashraf Ali | H15: 85 | I15: 55.4 | J15: 7
G16: Mohsyn Hassan | H16: 79 | I16: 51.2 | J16: 7
G17: Abdul Razzaq | H17: 66 | I17: 50.6 | J17: 7
... G51: Muhammad Sohan Ashiq | H51: 75 | I51: 34.7 | J51: 6

Sheet Term vs Class Test
A1: Term Exam vs Class Test Analysis – with Grade Classification
A3: STUDENT-LEVEL: Avg Term % vs Avg CT % with A/B/C/D/F Grades
A4: Student Name | B4: Grade | C4: Avg Term % | D4: Term Grade | E4: Avg CT % | F4: CT Grade | G4: CT–Term Gap | H4: Pattern Flag
A5: Abdullah Ayaz | B5: 7 | C5: 77.4 | D5: =IF(C5="","F",IF(C5>80,"A",IF(C5>=70,"B",IF(C5>=60,"C",IF(C5>=50,"D","F"))))) -> B | E5: 74.2 | F5: =IF(E5="","F",IF(E5>80,"A",IF(E5>=70,"B",IF(E5>=60,"C",IF(E5>=50,"D","F"))))) -> B | G5: -3.2 | H5: Consistent
A6: Omer Razi | B6: 7 | C6: 75.8 | D6: =IF(C6="","F",IF(C6>80,"A",IF(C6>=70,"B",IF(C6>=60,"C",IF(C6>=50,"D","F"))))) -> B | E6: 74.2 | F6: =IF(E6="","F",IF(E6>80,"A",IF(E6>=70,"B",IF(E6>=60,"C",IF(E6>=50,"D","F"))))) -> B | G6: -1.6 | H6: Consistent
A7: Muqaddas Jamal | B7: 7 | C7: 55.4 | D7: =IF(C7="","F",IF(C7>80,"A",IF(C7>=70,"B",IF(C7>=60,"C",IF(C7>=50,"D","F"))))) -> D | E7: 43.3 | F7: =IF(E7="","F",IF(E7>80,"A",IF(E7>=70,"B",IF(E7>=60,"C",IF(E7>=50,"D","F"))))) -> F | G7: -12.1 | H7: Consistent
A8: Hamnah Shafi | B8: 7 | C8: 56.7 | D8: =IF(C8="","F",IF(C8>80,"A",IF(C8>=70,"B",IF(C8>=60,"C",IF(C8>=50,"D","F"))))) -> D | E8: 52.4 | F8: =IF(E8="","F",IF(E8>80,"A",IF(E8>=70,"B",IF(E8>=60,"C",IF(E8>=50,"D","F"))))) -> D | G8: -4.3 | H8: Consistent
A9: Zeenia Zohaib | B9: 7 | C9: 42.5 | D9: =IF(C9="","F",IF(C9>80,"A",IF(C9>=70,"B",IF(C9>=60,"C",IF(C9>=50,"D","F"))))) -> F | E9: 50.7 | F9: =IF(E9="","F",IF(E9>80,"A",IF(E9>=70,"B",IF(E9>=60,"C",IF(E9>=50,"D","F"))))) -> D | G9: 8.2 | H9: Consistent
A10: Umer Adil | B10: 7 | C10: 63.5 | D10: =IF(C10="","F",IF(C10>80,"A",IF(C10>=70,"B",IF(C10>=60,"C",IF(C10>=50,"D","F"))))) -> C | E10: 69.8 | F10: =IF(E10="","F",IF(E10>80,"A",IF(E10>=70,"B",IF(E10>=60,"C",IF(E10>=50,"D","F"))))) -> C | G10: 6.3 | H10: Consistent
A11: Inayah Sabahat | B11: 7 | C11: 78.8 | D11: =IF(C11="","F",IF(C11>80,"A",IF(C11>=70,"B",IF(C11>=60,"C",IF(C11>=50,"D","F"))))) -> B | E11: 75.8 | F11: =IF(E11="","F",IF(E11>80,"A",IF(E11>=70,"B",IF(E11>=60,"C",IF(E11>=50,"D","F"))))) -> B | G11: -3 | H11: Consistent
A12: Ayaan Amin | B12: 7 | C12: 53.7 | D12: =IF(C12="","F",IF(C12>80,"A",IF(C12>=70,"B",IF(C12>=60,"C",IF(C12>=50,"D","F"))))) -> D | E12: 40.7 | F12: =IF(E12="","F",IF(E12>80,"A",IF(E12>=70,"B",IF(E12>=60,"C",IF(E12>=50,"D","F"))))) -> F | G12: -13 | H12: Consistent
A13: Muhammad Umer | B13: 7 | C13: 67.9 | D13: =IF(C13="","F",IF(C13>80,"A",IF(C13>=70,"B",IF(C13>=60,"C",IF(C13>=50,"D","F"))))) -> C | E13: 70.9 | F13: =IF(E13="","F",IF(E13>80,"A",IF(E13>=70,"B",IF(E13>=60,"C",IF(E13>=50,"D","F"))))) -> B | G13: 3 | H13: Consistent
A14: Hamza Naveed | B14: 7 | C14: 67.3 | D14: =IF(C14="","F",IF(C14>80,"A",IF(C14>=70,"B",IF(C14>=60,"C",IF(C14>=50,"D","F"))))) -> C | E14: 71.4 | F14: =IF(E14="","F",IF(E14>80,"A",IF(E14>=70,"B",IF(E14>=60,"C",IF(E14>=50,"D","F"))))) -> B | G14: 4.1 | H14: Consistent
A15: Omar Borra | B15: 7 | C15: 63.8 | D15: =IF(C15="","F",IF(C15>80,"A",IF(C15>=70,"B",IF(C15>=60,"C",IF(C15>=50,"D","F"))))) -> C | E15: 65.1 | F15: =IF(E15="","F",IF(E15>80,"A",IF(E15>=70,"B",IF(E15>=60,"C",IF(E15>=50,"D","F"))))) -> C | G15: 1.3 | H15: Consistent
A16: Umer Imran | B16: 7 | C16: 44.6 | D16: =IF(C16="","F",IF(C16>80,"A",IF(C16>=70,"B",IF(C16>=60,"C",IF(C16>=50,"D","F"))))) -> F | E16: 32.3 | F16: =IF(E16="","F",IF(E16>80,"A",IF(E16>=70,"B",IF(E16>=60,"C",IF(E16>=50,"D","F"))))) -> F | G16: -12.3 | H16: Consistent
... A52: Muhammad Hussain Raza | B52: 6 | C52: 46.4 | D52: =IF(C52="","F",IF(C52>80,"A",IF(C52>=70,"B",IF(C52>=60,"C",IF(C52>=50,"D","F"))))) -> F | E52: 57.5 | F52: =IF(E52="","F",IF(E52>80,"A",IF(E52>=70,"B",IF(E52>=60,"C",IF(E52>=50,"D","F"))))) -> D | G52: 11.1 | H52: Consistent
A55: SUMMARY STATISTICS – Formula Driven
A56: Metric | B56: Value
A57: Overall Avg Term % | E57: =AVERAGE(C5:C52) -> 62.304167
A58: Overall Avg CT % | E58: =AVERAGE(E5:E52) -> 61.59375
A59: # Grade A in Term | E59: =COUNTIF(D5:D52,"A") -> 3
A60: # Grade F in Term | E60: =COUNTIF(D5:D52,"F") -> 8
A61: Pearson r | E61: 0.749
A62: R² (CT explains) | E62: 0.5606
A63: Regression Equation | E63: ="Term % = 23.331 + 0.633 × CT %" -> Term % = 23.331 + 0.633 × CT %
A64: Students Consistent | E64: =COUNTIF(H5:H52,"Consistent") -> 45
A65: High CT / Low Term | E65: =COUNTIF(H5:H52,"High CT / Low Term") -> 0
A66: Low CT / High Term | E66: =COUNTIF(H5:H52,"Low CT / High Term") -> 3

Sheet Subject Performance
A1: Subject Performance Across Grades – Average Term Marks
A3: SECTION 1 – Average Term % per Subject (A/B/C/D/F Grade)
A4: Subject | B4: Grade 6 Avg % | C4: Grade 7 Avg % | D4: Grade 8 Avg % | E4: Overall Avg % | F4: Rank | G4: Subject Grade
A5: English Reading | B5: 71.2 | C5: 67.7 | D5: 64.9 | E5: =AVERAGE(B5:D5) -> 67.933333 | F5: 1 | G5: =IF(E5="","F",IF(E5>80,"A",IF(E5>=70,"B",IF(E5>=60,"C",IF(E5>=50,"D","F"))))) -> C
A6: Geography | B6: 63.4 | C6: 68.9 | D6: 67.3 | E6: =AVERAGE(B6:D6) -> 66.533333 | F6: 2 | G6: =IF(E6="","F",IF(E6>80,"A",IF(E6>=70,"B",IF(E6>=60,"C",IF(E6>=50,"D","F"))))) -> C
A7: Islamiat | B7: 64.8 | C7: 66.9 | D7: 61.4 | E7: =AVERAGE(B7:D7) -> 64.366667 | F7: 3 | G7: =IF(E7="","F",IF(E7>80,"A",IF(E7>=70,"B",IF(E7>=60,"C",IF(E7>=50,"D","F"))))) -> C
A8: History | B8: 76 | C8: 55 | D8: 60.6 | E8: =AVERAGE(B8:D8) -> 63.866667 | F8: 4 | G8: =IF(E8="","F",IF(E8>80,"A",IF(E8>=70,"B",IF(E8>=60,"C",IF(E8>=50,"D","F"))))) -> C
A9: Urdu | B9: 68.7 | C9: 62.9 | D9: 57.5 | E9: =AVERAGE(B9:D9) -> 63.033333 | F9: 5 | G9: =IF(E9="","F",IF(E9>80,"A",IF(E9>=70,"B",IF(E9>=60,"C",IF(E9>=50,"D","F"))))) -> C
A10: Mathematics | B10: 63.8 | C10: 66.1 | D10: 57.2 | E10: =AVERAGE(B10:D10) -> 62.366667 | F10: 6 | G10: =IF(E10="","F",IF(E10>80,"A",IF(E10>=70,"B",IF(E10>=60,"C",IF(E10>=50,"D","F"))))) -> C
A11: English Lit | B11: 64.3 | C11: 64.2 | D11: 54.1 | E11: =AVERAGE(B11:D11) -> 60.866667 | F11: 7 | G11: =IF(E11="","F",IF(E11>80,"A",IF(E11>=70,"B",IF(E11>=60,"C",IF(E11>=50,"D","F"))))) -> C
A12: Science | B12: 62.6 | C12: 61.2 | D12: 55.4 | E12: =AVERAGE(B12:D12) -> 59.733333 | F12: 8 | G12: =IF(E12="","F",IF(E12>80,"A",IF(E12>=70,"B",IF(E12>=60,"C",IF(E12>=50,"D","F"))))) -> D
A13: Computer Sci | B13: 65.4 | C13: 58.9 | D13: 52.7 | E13: =AVERAGE(B13:D13) -> 59 | F13: 9 | G13: =IF(E13="","F",IF(E13>80,"A",IF(E13>=70,"B",IF(E13>=60,"C",IF(E13>=50,"D","F"))))) -> D
A14: Arabic | B14: 59.7 | C14: 41.4 | D14: 55.8 | E14: =AVERAGE(B14:D14) -> 52.3 | F14: 10 | G14: =IF(E14="","F",IF(E14>80,"A",IF(E14>=70,"B",IF(E14>=60,"C",IF(E14>=50,"D","F"))))) -> D
A16: SECTION 2 – Cross-Grade Variation (Max–Min spread)
A17: Subject | B17: Grade 6 % | C17: Grade 7 % | D17: Grade 8 % | E17: Variation (Max-Min) | F17: Leading Grade
A18: History | B18: 76 | C18: 55 | D18: 60.6 | E18: =MAX(B18,C18,D18)-MIN(B18,C18,D18) -> 21 | F18: Grade 6
A19: Arabic | B19: 59.7 | C19: 41.4 | D19: 55.8 | E19: =MAX(B19,C19,D19)-MIN(B19,C19,D19) -> 18.3 | F19: Grade 6
A20: Computer Sci | B20: 65.4 | C20: 58.9 | D20: 52.7 | E20: =MAX(B20,C20,D20)-MIN(B20,C20,D20) -> 12.7 | F20: Grade 6
A21: Urdu | B21: 68.7 | C21: 62.9 | D21: 57.5 | E21: =MAX(B21,C21,D21)-MIN(B21,C21,D21) -> 11.2 | F21: Grade 6
A22: English Lit | B22: 64.3 | C22: 64.2 | D22: 54.1 | E22: =MAX(B22,C22,D22)-MIN(B22,C22,D22) -> 10.2 | F22: Grade 6
A23: Mathematics | B23: 63.8 | C23: 66.1 | D23: 57.2 | E23: =MAX(B23,C23,D23)-MIN(B23,C23,D23) -> 8.9 | F23: Grade 7

Sheet Teacher Analysis
A1: Teacher Performance Analysis – Avg Student Term Marks by Teacher
A3: SECTION 1 – Teacher × Subject × Grade: Avg Term % + Grade
A4: Teacher | B4: Subject | C4: Grade 6 % | D4: Grade 7 % | E4: Grade 8 % | F4: Overall Avg % | G4: # Students | H4: Performance Tag | I4: Grade
A5: Miss Javeria | B5: English Reading | C5: 71.2 | D5: — | E5: — | F5: 71.2 | G5: 18 | H5: Strong | I5: =IF(F5="","F",IF(F5>80,"A",IF(F5>=70,"B",IF(F5>=60,"C",IF(F5>=50,"D","F"))))) -> B
A6: Miss Farah | B6: Urdu | C6: 68.7 | D6: — | E6: — | F6: 68.7 | G6: 18 | H6: Average | I6: =IF(F6="","F",IF(F6>80,"A",IF(F6>=70,"B",IF(F6>=60,"C",IF(F6>=50,"D","F"))))) -> C
A7: Miss Uzma | B7: Geography | C7: 63.4 | D7: 68.9 | E7: 67.3 | F7: 66.5 | G7: 48 | H7: Average | I7: =IF(F7="","F",IF(F7>80,"A",IF(F7>=70,"B",IF(F7>=60,"C",IF(F7>=50,"D","F"))))) -> C
A8: Miss Ayesha | B8: English Reading | C8: — | D8: 67.7 | E8: 64.9 | F8: 66.3 | G8: 30 | H8: Average | I8: =IF(F8="","F",IF(F8>80,"A",IF(F8>=70,"B",IF(F8>=60,"C",IF(F8>=50,"D","F"))))) -> C
A9: Miss Uzma | B9: Islamiat | C9: 64.8 | D9: 66.9 | E9: 61.4 | F9: 64.4 | G9: 48 | H9: Average | I9: =IF(F9="","F",IF(F9>80,"A",IF(F9>=70,"B",IF(F9>=60,"C",IF(F9>=50,"D","F"))))) -> C
A10: Miss Javeria | B10: English Lit | C10: 64.3 | D10: — | E10: — | F10: 64.3 | G10: 18 | H10: Average | I10: =IF(F10="","F",IF(F10>80,"A",IF(F10>=70,"B",IF(F10>=60,"C",IF(F10>=50,"D","F"))))) -> C
A11: Miss Uzma | B11: History | C11: 76 | D11: 55 | E11: 60.6 | F11: 63.9 | G11: 48 | H11: Average | I11: =IF(F11="","F",IF(F11>80,"A",IF(F11>=70,"B",IF(F11>=60,"C",IF(F11>=50,"D","F"))))) -> C
A12: Miss Naureen | B12: Mathematics | C12: 63.8 | D12: — | E12: — | F12: 63.8 | G12: 18 | H12: Average | I12: =IF(F12="","F",IF(F12>80,"A",IF(F12>=70,"B",IF(F12>=60,"C",IF(F12>=50,"D","F"))))) -> C
A13: Sir Umar | B13: Mathematics | C13: — | D13: 66.1 | E13: 57.2 | F13: 61.6 | G13: 30 | H13: Average | I13: =IF(F13="","F",IF(F13>80,"A",IF(F13>=70,"B",IF(F13>=60,"C",IF(F13>=50,"D","F"))))) -> C
A14: Miss Raheela | B14: Urdu | C14: — | D14: 62.9 | E14: 57.5 | F14: 60.2 | G14: 30 | H14: Average | I14: =IF(F14="","F",IF(F14>80,"A",IF(F14>=70,"B",IF(F14>=60,"C",IF(F14>=50,"D","F"))))) -> C
A15: Miss Ayesha | B15: Science | C15: 62.6 | D15: 61.2 | E15: 55.4 | F15: 59.7 | G15: 48 | H15: Average | I15: =IF(F15="","F",IF(F15>80,"A",IF(F15>=70,"B",IF(F15>=60,"C",IF(F15>=50,"D","F"))))) -> D
A16: Miss Ayesha | B16: English Lit | C16: — | D16: 64.2 | E16: 54.1 | F16: 59.2 | G16: 30 | H16: Average | I16: =IF(F16="","F",IF(F16>80,"A",IF(F16>=70,"B",IF(F16>=60,"C",IF(F16>=50,"D","F"))))) -> D
A17: Sir Danish | B17: Arabic | C17: 59.7 | D17: 41.4 | E17: 55.9 | F17: 52.3 | G17: 48 | H17: Needs Review | I17: =IF(F17="","F",IF(F17>80,"A",IF(F17>=70,"B",IF(F17>=60,"C",IF(F17>=50,"D","F"))))) -> D
A20: SECTION 2 – Teacher Overall Summary
A21: Teacher | B21: Subjects Taught | C21: Avg % (All) | D21: Grade
A22: Miss Farah | B22: Urdu | C22: 68.7 | D22: =IF(C22="","F",IF(C22>80,"A",IF(C22>=70,"B",IF(C22>=60,"C",IF(C22>=50,"D","F"))))) -> C
A23: Miss Javeria | B23: English Lit, English Reading | C23: 67.8 | D23: =IF(C23="","F",IF(C23>80,"A",IF(C23>=70,"B",IF(C23>=60,"C",IF(C23>=50,"D","F"))))) -> C
A24: Miss Uzma | B24: Geography, History, Islamiat | C24: 65.1 | D24: =IF(C24="","F",IF(C24>80,"A",IF(C24>=70,"B",IF(C24>=60,"C",IF(C24>=50,"D","F"))))) -> C
A25: Miss Naureen | B25: Mathematics | C25: 63.8 | D25: =IF(C25="","F",IF(C25>80,"A",IF(C25>=70,"B",IF(C25>=60,"C",IF(C25>=50,"D","F"))))) -> C
A26: Sir Umar | B26: Mathematics | C26: 61.9 | D26: =IF(C26="","F",IF(C26>80,"A",IF(C26>=70,"B",IF(C26>=60,"C",IF(C26>=50,"D","F"))))) -> C
A27: Miss Ayesha | B27: English Lit, English Reading, Science | C27: 61.6 | D27: =IF(C27="","F",IF(C27>80,"A",IF(C27>=70,"B",IF(C27>=60,"C",IF(C27>=50,"D","F"))))) -> C
A28: Miss Raheela | B28: Urdu | C28: 60.4 | D28: =IF(C28="","F",IF(C28>80,"A",IF(C28>=70,"B",IF(C28>=60,"C",IF(C28>=50,"D","F"))))) -> C
A29: Sir Danish | B29: Arabic | C29: 52.5 | D29: =IF(C29="","F",IF(C29>80,"A",IF(C29>=70,"B",IF(C29>=60,"C",IF(C29>=50,"D","F"))))) -> D

Sheet Transition Matrix
B1: TRANSITION MATRIX — Class Test Grade → Term Exam Grade (A / B / C / D / F)
B2: Grade Scale: A = >80% | B = 70–79% | C = 60–69% | D = 50–59% | F = <50% | ROW = CT Grade (FROM) → COLUMN = Term Grade (TO)
B4: MATRIX A — COUNT (CT Grade → Term Grade, how many students) | J4: Student | K4: Grade | L4: CT % | M4: Term % | N4: CT Grade | O4: Term Grade
B5: FROM ↓ TO → | C5: A | D5: B | E5: C | F5: D | G5: F | H5: Row Total | J5: Abdullah Ayaz | K5: 7 | L5: 74.2 | M5: 77.4 | N5: B | O5: B
B6: A | C6: =COUNTIFS($N$5:$N$52,"A",$O$5:$O$52,"A") -> 1 | D6: =COUNTIFS($N$5:$N$52,"A",$O$5:$O$52,"B") -> 3 | E6: =COUNTIFS($N$5:$N$52,"A",$O$5:$O$52,"C") -> 0 | F6: =COUNTIFS($N$5:$N$52,"A",$O$5:$O$52,"D") -> 0 | G6: =COUNTIFS($N$5:$N$52,"A",$O$5:$O$52,"F") -> 0 | H6: =SUM(C6:G6) -> 4 | J6: Omer Razi | K6: 7 | L6: 74.2 | M6: 75.8 | N6: B | O6: B
B7: B | C7: =COUNTIFS($N$5:$N$52,"B",$O$5:$O$52,"A") -> 1 | D7: =COUNTIFS($N$5:$N$52,"B",$O$5:$O$52,"B") -> 6 | E7: =COUNTIFS($N$5:$N$52,"B",$O$5:$O$52,"C") -> 6 | F7: =COUNTIFS($N$5:$N$52,"B",$O$5:$O$52,"D") -> 0 | G7: =COUNTIFS($N$5:$N$52,"B",$O$5:$O$52,"F") -> 0 | H7: =SUM(C7:G7) -> 13 | J7: Muqaddas Jamal | K7: 7 | L7: 43.3 | M7: 55.4 | N7: F | O7: D
B8: C | C8: =COUNTIFS($N$5:$N$52,"C",$O$5:$O$52,"A") -> 0 | D8: =COUNTIFS($N$5:$N$52,"C",$O$5:$O$52,"B") -> 1 | E8: =COUNTIFS($N$5:$N$52,"C",$O$5:$O$52,"C") -> 6 | F8: =COUNTIFS($N$5:$N$52,"C",$O$5:$O$52,"D") -> 2 | G8: =COUNTIFS($N$5:$N$52,"C",$O$5:$O$52,"F") -> 0 | H8: =SUM(C8:G8) -> 9 | J8: Hamnah Shafi | K8: 7 | L8: 52.4 | M8: 56.7 | N8: D | O8: D
B9: D | C9: =COUNTIFS($N$5:$N$52,"D",$O$5:$O$52,"A") -> 0 | D9: =COUNTIFS($N$5:$N$52,"D",$O$5:$O$52,"B") -> 0 | E9: =COUNTIFS($N$5:$N$52,"D",$O$5:$O$52,"C") -> 0 | F9: =COUNTIFS($N$5:$N$52,"D",$O$5:$O$52,"D") -> 7 | G9: =COUNTIFS($N$5:$N$52,"D",$O$5:$O$52,"F") -> 3 | H9: =SUM(C9:G9) -> 10 | J9: Zeenia Zohaib | K9: 7 | L9: 50.7 | M9: 42.5 | N9: D | O9: F
B10: F | C10: =COUNTIFS($N$5:$N$52,"F",$O$5:$O$52,"A") -> 1 | D10: =COUNTIFS($N$5:$N$52,"F",$O$5:$O$52,"B") -> 1 | E10: =COUNTIFS($N$5:$N$52,"F",$O$5:$O$52,"C") -> 1 | F10: =COUNTIFS($N$5:$N$52,"F",$O$5:$O$52,"D") -> 4 | G10: =COUNTIFS($N$5:$N$52,"F",$O$5:$O$52,"F") -> 5 | H10: =SUM(C10:G10) -> 12 | J10: Umer Adil | K10: 7 | L10: 69.8 | M10: 63.5 | N10: C | O10: C
B11: Col Total | C11: =SUM(C6:C10) -> 3 | D11: =SUM(D6:D10) -> 11 | E11: =SUM(E6:E10) -> 13 | F11: =SUM(F6:F10) -> 13 | G11: =SUM(G6:G10) -> 8 | H11: =SUM(H6:H10) -> 48 | J11: Inayah Sabahat | K11: 7 | L11: 75.8 | M11: 78.8 | N11: B | O11: B
J12: Ayaan Amin | K12: 7 | L12: 40.7 | M12: 53.7 | N12: F | O12: D
J13: Muhammad Umer | K13: 7 | L13: 70.9 | M13: 67.9 | N13: B | O13: C
B14: MATRIX B — TRANSITION PROBABILITY (prob of CT Grade → Term Grade) | J14: Hamza Naveed | K14: 7 | L14: 71.4 | M14: 67.3 | N14: B | O14: C
B15: FROM ↓ TO → | C15: A | D15: B | E15: C | F15: D | G15: F | H15: Sum | J15: Omar Borra | K15: 7 | L15: 65.1 | M15: 63.8 | N15: C | O15: C
B16: A | C16: =IFERROR(C6/H6,0) -> 0.25 | D16: =IFERROR(D6/H6,0) -> 0.75 | E16: =IFERROR(E6/H6,0) -> 0 | F16: =IFERROR(F6/H6,0) -> 0 | G16: =IFERROR(G6/H6,0) -> 0 | H16: =SUM(C16:G16) -> 1 | J16: Umer Imran | K16: 7 | L16: 32.3 | M16: 44.6 | N16: F | O16: F
B17: B | C17: =IFERROR(C7/H7,0) -> 0.076923077 | D17: =IFERROR(D7/H7,0) -> 0.46153846 | E17: =IFERROR(E7/H7,0) -> 0.46153846 | F17: =IFERROR(F7/H7,0) -> 0 | G17: =IFERROR(G7/H7,0) -> 0 | H17: =SUM(C17:G17) -> 1 | J17: Ayaan Ashraf Ali | K17: 7 | L17: 57.3 | M17: 54.2 | N17: D | O17: D
B18: C | C18: =IFERROR(C8/H8,0) -> 0 | D18: =IFERROR(D8/H8,0) -> 0.11111111 | E18: =IFERROR(E8/H8,0) -> 0.66666667 | F18: =IFERROR(F8/H8,0) -> 0.22222222 | G18: =IFERROR(G8/H8,0) -> 0 | H18: =SUM(C18:G18) -> 1 | J18: Mohsyn Hassan | K18: 7 | L18: 51.8 | M18: 50.7 | N18: D | O18: D
B19: D | C19: =IFERROR(C9/H9,0) -> 0 | D19: =IFERROR(D9/H9,0) -> 0 | E19: =IFERROR(E9/H9,0) -> 0 | F19: =IFERROR(F9/H9,0) -> 0.7 | G19: =IFERROR(G9/H9,0) -> 0.3 | H19: =SUM(C19:G19) -> 1 | J19: Abdul Razzaq | K19: 7 | L19: 44 | M19: 55 | N19: F | O19: D
B20: F | C20: =IFERROR(C10/H10,0) -> 0.083333333 | D20: =IFERROR(D10/H10,0) -> 0.083333333 | E20: =IFERROR(E10/H10,0) -> 0.083333333 | F20: =IFERROR(F10/H10,0) -> 0.33333333 | G20: =IFERROR(G10/H10,0) -> 0.41666667 | H20: =SUM(C20:G20) -> 1 | J20: Ayan Umar | K20: 7 | L20: 66 | M20: 73.5 | N20: C | O20: B
J21: Mahad Sajid | K21: 8 | L21: 69.5 | M21: 64.2 | N21: C | O21: C
J22: Fatima Abdul Qadir | K22: 8 | L22: 73.9 | M22: 73.6 | N22: B | O22: B
J23: Syed Muzzammil Hassan | K23: 8 | L23: 58 | M23: 54.8 | N23: D | O23: D
B24: SECTION 3 — STUDENT MOVEMENT (CT Grade → Term Grade) | J24: Mirha Farhan | K24: 8 | L24: 46.7 | M24: 52.4 | N24: F | O24: D
B25: Student | C25: Grade | D25: CT % | E25: CT Grade | F25: Term % | G25: Term Grade | H25: Movement | J25: Abeeha Ali Khan | K25: 8 | L25: 78 | M25: 80.4 | N25: B | O25: A
B26: Muhammad Ahmed Ahsan | C26: 6 | D26: 84.6 | E26: A | F26: 77.8 | G26: B | H26: Declined | J26: Muhammad Hussain Yawar | K26: 8 | L26: 37.1 | M26: 40.4 | N26: F | O26: F
B27: Zainab Shoaib | C27: 6 | D27: 65.9 | E27: C | F27: 62.6 | G27: C | H27: Same | J27: Muhammad Yahya | K27: 8 | L27: 77.4 | M27: 75.6 | N27: B | O27: B
B28: Muhammad Ayaan G6 | C28: 6 | D28: 71 | E28: B | F28: 69.3 | G28: C | H28: Declined | J28: Alishba Haider | K28: 8 | L28: 37.7 | M28: 42.1 | N28: F | O28: F
B29: Aahid Manzoor | C29: 6 | D29: 73.8 | E29: B | F29: 63.2 | G29: C | H29: Declined | J29: Ali Hasan | K29: 8 | L29: 40.4 | M29: 45.2 | N29: F | O29: F
B30: Rohaan Talha | C30: 6 | D30: 73.3 | E30: B | F30: 67.2 | G30: C | H30: Declined | J30: Amna Awais | K30: 8 | L30: 64.1 | M30: 69.2 | N30: C | O30: C
B31: Eeshal Amin | C31: 6 | D31: 85.9 | E31: A | F31: 81.3 | G31: A | H31: Same | J31: Ayesha Awais | K31: 8 | L31: 53.8 | M31: 54.3 | N31: D | O31: D
B32: Muhammad Sarhan Safder | C32: 6 | D32: 79.7 | E32: B | F32: 79.3 | G32: B | H32: Same | J32: Mahum Rehman | K32: 8 | L32: 58.4 | M32: 58.7 | N32: D | O32: D
B33: Mohammad Omar Abid | C33: 6 | D33: 47 | E33: F | F33: 64.2 | G33: C | H33: Improved | J33: Muhammad G8 | K33: 8 | L33: 39.9 | M33: 73 | N33: F | O33: B
B34: Syed Huzaifa Quadri | C34: 6 | D34: 65.8 | E34: C | F34: 67.2 | G34: C | H34: Same | J34: Muhammad Ahmed G8 | K34: 8 | L34: 44.1 | M34: 38.2 | N34: F | O34: F
B35: Zoraiz Jameel | C35: 6 | D35: 58.9 | E35: D | F35: 54.1 | G35: D | H35: Same | J35: Muhammad Ahmed Ahsan | K35: 6 | L35: 84.6 | M35: 77.8 | N35: A | O35: B
B36: Anaya Rameez | C36: 6 | D36: 70.5 | E36: B | F36: 63.6 | G36: C | H36: Declined | J36: Zainab Shoaib | K36: 6 | L36: 65.9 | M36: 62.6 | N36: C | O36: C
B37: Anaya Hammad | C37: 6 | D37: 63.2 | E37: C | F37: 56.2 | G37: D | H37: Declined | J37: Muhammad Ayaan G6 | K37: 6 | L37: 71 | M37: 69.3 | N37: B | O37: C
... B52: Muhammad Umer | C52: 7 | D52: 70.9 | E52: B | F52: 67.9 | G52: C | H52: Declined | J52: Muhammad Hussain Raza | K52: 6 | L52: 57.5 | M52: 46.4 | N52: D | O52: F
B53: Hamza Naveed | C53: 7 | D53: 71.4 | E53: B | F53: 67.3 | G53: C | H53: Declined
B54: Omar Borra | C54: 7 | D54: 65.1 | E54: C | F54: 63.8 | G54: C | H54: Same
B55: Umer Imran | C55: 7 | D55: 32.3 | E55: F | F55: 44.6 | G55: F | H55: Same
...

Sheet Prediction of Final Term 
A1: Student Name | B1: Grade | C1: CT2 Percentage | D1: CT2 Grade | F1: Column1 | G1: Count | H1: % | T1: =(G2*'Prediction of Final Term '!C16 + 'Prediction of Final Term '!H3*'Prediction of Final Term '!C17 + 'Prediction of Final Term '!H4*'Prediction of Final Term '!C18 +'Prediction of Final Term '!H5*'Prediction of Final Term '!C19 +'Prediction of Final Term '!H6*'Prediction of Final Term '!C20)/100 -> 2.4639961
A2: Umaiza Omer | B2: Grade 6 | C2: 87.08 | D2: A | F2: A | G2: =COUNTIF(D:D, "A") -> 4 | H2: =COUNTIF(D:D, "A") / (COUNTA(A:A) - 1) -> 0.078431373
A3: Eeshal Amin | B3: Grade 6 | C3: 85.42 | D3: A | F3: B | G3: =COUNTIF(D:D, "B") -> 10 | H3: =COUNTIF(D:D, "B") / (COUNTA(A:A) - 1) -> 0.19607843
A4: Raayan Ibrahim | B4: Grade 6 | C4: 85 | D4: A | F4: C | G4: =COUNTIF(D:D, "C") -> 16 | H4: =COUNTIF(D:D, "C") / (COUNTA(A:A) - 1) -> 0.31372549
A5: Muhammad Sarhan Safder | B5: Grade 6 | C5: 79.58 | D5: B | F5: D | G5: =COUNTIF(D:D, "D") -> 9 | H5: =COUNTIF(D:D, "D") / (COUNTA(A:A) - 1) -> 0.17647059
A6: Jannah Saqib | B6: Grade 6 | C6: 78.75 | D6: B | F6: F | G6: =COUNTIF(D:D, "F") -> 12 | H6: =COUNTIF(D:D, "F") / (COUNTA(A:A) - 1) -> 0.23529412
A7: Muhammad Ahmed Ahsan | B7: Grade 6 | C7: 76.67 | D7: B
A8: Rohaan Talha | B8: Grade 6 | C8: 70 | D8: B | N8: Final Grade | O8: Predicted Probability | P8: Projected Student count
A9: Anaya Rameez | B9: Grade 6 | C9: 69.58 | D9: C | N9: A | O9: 5 | P9: 3
A10: Zoraiz Jameel | B10: Grade 6 | C10: 67.5 | D10: C | N10: B | O10: 20 | P10: 10
A11: Syed Huzaifa Quadri | B11: Grade 6 | C11: 64.58 | D11: C | N11: C | O11: 32 | P11: 16
A12: Aahid Manzoor | B12: Grade 6 | C12: 64.17 | D12: C | N12: D | O12: 27 | P12: 14
A13: Muhammad Ayaan | B13: Grade 6 | C13: 63.33 | D13: C | N13: F | O13: 15 | P13: 8
A14: Zainab Shoaib | B14: Grade 6 | C14: 55.42 | D14: D
A15: Muhammad Hussain Raza | B15: Grade 6 | C15: 53.75 | D15: D
A16: Mohammad Omar Abid | B16: Grade 6 | C16: 52.08 | D16: D
A17: Anaya Hammad | B17: Grade 6 | C17: 48.75 | D17: F
A18: Aysel Hammad | B18: Grade 6 | C18: 47.08 | D18: F
A19: Alisha Arif | B19: Grade 6 | C19: 42.92 | D19: F
A20: Muhammad Sohan Ashiq | B20: Grade 6 | C20: 26.25 | D20: F
A21: Abdullah Ahmed | B21: Grade 6 | C21: 4.5 | D21: F | F21: Grade | G21: Midterm Count (Actual) | H21: Final (Predicted)
A22: Hafsa Salman | B22: Grade 6 | C22: 0 | D22: F | F22: A | G22: 4 | H22: 3
A23: Omar Borra | B23: Grade 7 | C23: 73.88 | D23: B | F23: B | G23: 13 | H23: 10
A24: Omer Razi | B24: Grade 7 | C24: 72.24 | D24: B | F24: C | G24: 9 | H24: 16
A25: Abdullah Ayaz | B25: Grade 7 | C25: 68.57 | D25: C | F25: D | G25: 10 | H25: 14
A26: Inayah Sabahat | B26: Grade 7 | C26: 67.76 | D26: C | F26: F | G26: 12 | H26: 8
A27: Umer Adil | B27: Grade 7 | C27: 65.71 | D27: C | F27: Total | G27: 48
A28: Muhammad Umer | B28: Grade 7 | C28: 65.31 | D28: C
A29: Ayan Umar | B29: Grade 7 | C29: 63.67 | D29: C
A30: Ayaan Amin | B30: Grade 7 | C30: 63.27 | D30: C
A31: Mohsyn Hassan | B31: Grade 7 | C31: 62.04 | D31: C
A32: Hamza Naveed | B32: Grade 7 | C32: 60 | D32: C
A33: Ayaan Ashraf Ali | B33: Grade 7 | C33: 59.59 | D33: D
A34: Hamnah Shafi | B34: Grade 7 | C34: 54.29 | D34: D
A35: Muqaddas jamal | B35: Grade 7 | C35: 53.47 | D35: D
A36: Zeenia Zohaib | B36: Grade 7 | C36: 45.71 | D36: F
A37: Abdul Razzaq | B37: Grade 7 | C37: 41.63 | D37: F
A38: Umer imran | B38: Grade 7 | C38: 2.45 | D38: F
A39: Abeeha Ali Khan | B39: Grade 8 | C39: 80.38 | D39: A
... A52: Muhammad Hussain Yawar | B52: Grade 8 | C52: 42.26 | D52: F
